<?xml version="1.0" ?>
<robot name="Thesis" xmlns:xacro="http://www.ros.org/wiki/xacro">
  
  <!-- BGN - Include -->
  <xacro:include filename="$(find thesis_description)/urdf/links_joints.xacro" />
  <xacro:include filename="$(find thesis_description)/urdf/gazebo.xacro" />
  <!-- END - Include -->
  
  <material name="white">
    <color rgba="1 1 1 1"/>
  </material>

  <material name="black">
    <color rgba="0 0 0 1"/>
  </material>

  <material name="blue">
    <color rgba="0 0 1 1"/>
  </material>

  <!-- BGN - Robot description -->
  <m_link_mesh name="base_link"
              origin_rpy="1.5807 0 1.5807" origin_xyz="0 0 0.03"
              mass="5.0"
              ixx="1.3235" ixy="0" ixz="0"
              iyy="1.3235" iyz="0"
              izz="0.9655"
              material="white"
              meshfile="package://thesis_description/meshes/base.stl"
              meshscale="0.001 0.001 0.001" />

  <joint name="cuerpo__ruedafrentederecha" type="continuous">
      <parent link="base_link"/>
      <child link="ruedafrentederecha"/>
      <origin xyz="0.21 -0.30 -0.05" rpy="0.0 0.0 0"/>
      <axis xyz="0 1 0"/>
  </joint>

  <m_link_mesh name="ruedafrentederecha"
              origin_rpy="1.5807 0 3.1416" origin_xyz="0 0 0"
              mass="2"
              ixx="0.132" ixy="0" ixz="0"
              iyy="0.132" iyz="0"
              izz="0.097"
              material="black"
              meshfile="package://thesis_description/meshes/Rueda.stl"
              meshscale="0.0009 0.0009 0.0009" />

  <joint name="cuerpo__ruedatraseraderecha" type="continuous">
      <parent link="base_link"/>
      <child link="ruedatraseraderecha"/>
      <origin xyz="-0.20 -0.30 -0.05" rpy="0.0 0.0 0"/>
      <axis xyz="0 1 0"/>
  </joint>

  <m_link_mesh name="ruedatraseraderecha"
              origin_rpy="1.5807 0 3.1416" origin_xyz="0 0 0"
              mass="2"
              ixx="0.132" ixy="0" ixz="0"
              iyy="0.132" iyz="0"
              izz="0.097"
              material="black"
              meshfile="package://thesis_description/meshes/Rueda.stl"
              meshscale="0.0009 0.0009 0.0009" />

  <joint name="cuerpo__ruedafrenteizquierda" type="continuous">
      <parent link="base_link"/>
      <child link="ruedafrenteizquierda"/>
      <origin xyz="0.21 0.30 -0.05" rpy="0.0 0.0 0"/>
      <axis xyz="0 1 0"/>
  </joint>

  <m_link_mesh name="ruedafrenteizquierda"
              origin_rpy="1.5807 0 3.1416" origin_xyz="0 0 0"
              mass="2"
              ixx="0.132" ixy="0" ixz="0"
              iyy="0.132" iyz="0"
              izz="0.097"
              material="black"
              meshfile="package://thesis_description/meshes/Rueda.stl"
              meshscale="0.0009 0.0009 0.0009" />

  <joint name="cuerpo__ruedatraseraizquierda" type="continuous">
      <parent link="base_link"/>
      <child link="ruedatraseraizquierda"/>
      <origin xyz="-0.20 0.30 -0.05" rpy="0.0 0.0 0"/>
      <axis xyz="0 1 0"/>
  </joint>

  <m_link_mesh name="ruedatraseraizquierda"
              origin_rpy="1.5807 0 3.1416" origin_xyz="0 0 0"
              mass="2"
              ixx="0.132" ixy="0" ixz="0"
              iyy="0.132" iyz="0"
              izz="0.097"
              material="black"
              meshfile="package://thesis_description/meshes/Rueda.stl"
              meshscale="0.0009 0.0009 0.0009" />

</robot>
